{"name": "Проверка сообщения об ошибке при попытке получения заказов неавторизованным пользователем", "status": "passed", "start": 1737273833949, "stop": 1737273834092, "uuid": "3d71beac-7d60-47f9-87b8-5d0c4139114c", "historyId": "755596d46611e98c698b1244a1014b74", "testCaseId": "755596d46611e98c698b1244a1014b74", "fullName": "tests.test_get_orders.TestGetUserOrders#test_get_orders_unauthorized_user_message", "labels": [{"name": "parentSuite", "value": "tests"}, {"name": "suite", "value": "test_get_orders"}, {"name": "subSuite", "value": "TestGetUserOrders"}, {"name": "host", "value": "SergeiBazhenov"}, {"name": "thread", "value": "12572-MainThread"}, {"name": "framework", "value": "pytest"}, {"name": "language", "value": "cpython3"}, {"name": "package", "value": "tests.test_get_orders"}]}